Workbook

Sheet Inputs
A1: Commercial Real Estate Investment Model
A2: Industrial Warehouse - Bay Area
A4: PROPERTY DETAILS
A5: Building Size (SF) | B5: 50000
A6: Purchase Price | B6: 10000000
A7: Price per SF | B7: =B6/B5 -> 200
A8: Closing Costs (% of Price) | B8: 0.03
A9: Total Acquisition Cost | B9: =B6*(1+B8) -> 10300000
A11: FINANCING STRUCTURE
A12: Down Payment % | B12: 0.25
A13: Equity Required | B13: =B9*B12 -> 2575000
A14: Loan Amount | B14: =B9-B13 -> 7725000
A15: Interest Rate | B15: 0.07
A16: Loan Term (Years) | B16: 25
A17: Annual Debt Service | B17: =PMT(B15,B16,-B14) -> 662886.25
A18: Monthly Debt Service | B18: =B17/12 -> 55240.52
A20: REVENUE ASSUMPTIONS
A21: Annual Base Rent per SF (NNN) | B21: 18
A22: Rent Growth Rate (Annual) | B22: 0.03
A23: Stabilized Occupancy % | B23: 0.95
A24: Year 1 Occupancy % | B24: 0.9
A25: Other Income (% of Rent) | B25: 0.02
A27: OPERATING EXPENSES (NNN)
A28: Property Taxes ($/SF) | B28: 1.5
A29: Property Insurance ($/SF) | B29: 0.75
A30: CAM ($/SF) | B30: 1.25
A31: Expense Growth Rate | B31: 0.025
A33: LANDLORD EXPENSES
A34: Property Management (% Rev) | B34: 0.04
A35: Leasing Commissions (% Rent) | B35: 0.03
A36: Repairs & Maintenance ($/SF) | B36: 0.5
A38: CAPITAL EXPENDITURES
A39: Initial TI ($/SF) | B39: 5
A40: Annual CapEx Reserve ($/SF) | B40: 0.75
A42: EXIT ASSUMPTIONS (Year 10)
A43: Exit Cap Rate | B43: 0.065
A44: Sale Costs (%) | B44: 0.02
A46: ANALYSIS PARAMETERS
A47: Discount Rate for NPV | B47: 0.1
A48: Target IRR | B48: 0.15
...

Sheet Pro Forma
A1: 10-Year Pro Forma Operating Statement
A3: Year | B3: Year 0 | C3: Year 1 | D3: Year 2 | E3: Year 3 | F3: Year 4 | G3: Year 5 | H3: Year 6 | I3: Year 7 | J3: Year 8 | K3: Year 9 | L3: Year 10
A5: REVENUE | N5: =L25*(1+Inputs!$B$22) -> 1064926.8
A6: Base Rent ($/SF) | B6: 0 | C6: =Inputs!$B$21 -> 18 | D6: =C6*(1+Inputs!$B$22) -> 18.54 | E6: =D6*(1+Inputs!$B$22) -> 19.0962 | F6: =E6*(1+Inputs!$B$22) -> 19.669086 | G6: =F6*(1+Inputs!$B$22) -> 20.259159 | H6: =G6*(1+Inputs!$B$22) -> 20.866933 | I6: =H6*(1+Inputs!$B$22) -> 21.492941 | J6: =I6*(1+Inputs!$B$22) -> 22.13773 | K6: =J6*(1+Inputs!$B$22) -> 22.801861 | L6: =K6*(1+Inputs!$B$22) -> 23.485917 | N6: =N5/Inputs!$B$43 -> 16383490
A7: Occupancy % | B7: 0 | C7: =Inputs!$B$24 -> 0.9 | D7: =Inputs!$B$23 -> 0.95 | E7: =Inputs!$B$23 -> 0.95 | F7: =Inputs!$B$23 -> 0.95 | G7: =Inputs!$B$23 -> 0.95 | H7: =Inputs!$B$23 -> 0.95 | I7: =Inputs!$B$23 -> 0.95 | J7: =Inputs!$B$23 -> 0.95 | K7: =Inputs!$B$23 -> 0.95 | L7: =Inputs!$B$23 -> 0.95 | N7: =N6*Inputs!$B$44 -> 327669.8
A8: Occupied SF | B8: 0 | C8: =Inputs!$B$5*C7 -> 45000 | D8: =Inputs!$B$5*D7 -> 47500 | E8: =Inputs!$B$5*E7 -> 47500 | F8: =Inputs!$B$5*F7 -> 47500 | G8: =Inputs!$B$5*G7 -> 47500 | H8: =Inputs!$B$5*H7 -> 47500 | I8: =Inputs!$B$5*I7 -> 47500 | J8: =Inputs!$B$5*J7 -> 47500 | ... L8: =Inputs!$B$5*L7 -> 47500 | N8: =N6-N7 -> 16055820
A9: Gross Rental Income | B9: 0 | C9: =C6*C8 -> 810000 | D9: =D6*D8 -> 880650 | E9: =E6*E8 -> 907069.5 | F9: =F6*F8 -> 934281.58 | G9: =G6*G8 -> 962310.03 | H9: =H6*H8 -> 991179.33 | I9: =I6*I8 -> 1020914.7 | J9: =J6*J8 -> 1051542.2 | ... L9: =L6*L8 -> 1115581.1 | N9: =FV(Inputs!$B$15,10,-Inputs!$B$17,Inputs!$B$14) -> -6037510.9
A10: Other Income | B10: 0 | C10: =C9*Inputs!$B$25 -> 16200 | D10: =D9*Inputs!$B$25 -> 17613 | E10: =E9*Inputs!$B$25 -> 18141.39 | F10: =F9*Inputs!$B$25 -> 18685.632 | G10: =G9*Inputs!$B$25 -> 19246.201 | H10: =H9*Inputs!$B$25 -> 19823.587 | I10: =I9*Inputs!$B$25 -> 20418.294 | J10: =J9*Inputs!$B$25 -> 21030.843 | ... L10: =L9*Inputs!$B$25 -> 22311.621 | N10: =N8+N9 -> 10018309
A11: TOTAL REVENUE | B11: 0 | C11: =C10+C9 -> 826200 | D11: =D10+D9 -> 898263 | E11: =E10+E9 -> 925210.89 | F11: =F10+F9 -> 952967.22 | G11: =G10+G9 -> 981556.23 | H11: =H10+H9 -> 1011002.9 | I11: =I10+I9 -> 1041333 | J11: =J10+J9 -> 1072573 | ... L11: =L10+L9 -> 1137892.7
A13: OPERATING EXPENSES (Reimbursed)
A14: Property Taxes | B14: 0 | C14: =Inputs!$B$5*Inputs!$B$28 -> 75000 | D14: =C14*(1+Inputs!$B$31) -> 76875 | E14: =D14*(1+Inputs!$B$31) -> 78796.875 | F14: =E14*(1+Inputs!$B$31) -> 80766.797 | G14: =F14*(1+Inputs!$B$31) -> 82785.967 | H14: =G14*(1+Inputs!$B$31) -> 84855.616 | I14: =H14*(1+Inputs!$B$31) -> 86977.006 | J14: =I14*(1+Inputs!$B$31) -> 89151.432 | K14: =J14*(1+Inputs!$B$31) -> 91380.217 | L14: =K14*(1+Inputs!$B$31) -> 93664.723
A15: Property Insurance | B15: 0 | C15: =Inputs!$B$5*Inputs!$B$29 -> 37500 | D15: =C15*(1+Inputs!$B$31) -> 38437.5 | E15: =D15*(1+Inputs!$B$31) -> 39398.438 | F15: =E15*(1+Inputs!$B$31) -> 40383.398 | G15: =F15*(1+Inputs!$B$31) -> 41392.983 | H15: =G15*(1+Inputs!$B$31) -> 42427.808 | I15: =H15*(1+Inputs!$B$31) -> 43488.503 | J15: =I15*(1+Inputs!$B$31) -> 44575.716 | K15: =J15*(1+Inputs!$B$31) -> 45690.109 | L15: =K15*(1+Inputs!$B$31) -> 46832.361
A16: Common Area Maintenance | B16: 0 | C16: =Inputs!$B$5*Inputs!$B$30 -> 62500 | D16: =C16*(1+Inputs!$B$31) -> 64062.5 | E16: =D16*(1+Inputs!$B$31) -> 65664.062 | F16: =E16*(1+Inputs!$B$31) -> 67305.664 | G16: =F16*(1+Inputs!$B$31) -> 68988.306 | H16: =G16*(1+Inputs!$B$31) -> 70713.013 | I16: =H16*(1+Inputs!$B$31) -> 72480.839 | J16: =I16*(1+Inputs!$B$31) -> 74292.86 | K16: =J16*(1+Inputs!$B$31) -> 76150.181 | L16: =K16*(1+Inputs!$B$31) -> 78053.936
A17: Total Reimbursable Expenses | B17: 0 | C17: =SUM(C14:C16) -> 175000 | D17: =SUM(D14:D16) -> 179375 | E17: =SUM(E14:E16) -> 183859.38 | F17: =SUM(F14:F16) -> 188455.86 | G17: =SUM(G14:G16) -> 193167.26 | H17: =SUM(H14:H16) -> 197996.44 | I17: =SUM(I14:I16) -> 202946.35 | J17: =SUM(J14:J16) -> 208020.01 | ... L17: =SUM(L14:L16) -> 218551.02
A19: LANDLORD EXPENSES
A20: Property Management | B20: 0 | C20: =C11*Inputs!$B$34 -> 33048 | D20: =D11*Inputs!$B$34 -> 35930.52 | E20: =E11*Inputs!$B$34 -> 37008.436 | F20: =F11*Inputs!$B$34 -> 38118.689 | G20: =G11*Inputs!$B$34 -> 39262.249 | H20: =H11*Inputs!$B$34 -> 40440.117 | I20: =I11*Inputs!$B$34 -> 41653.32 | J20: =J11*Inputs!$B$34 -> 42902.92 | ... L20: =L11*Inputs!$B$34 -> 45515.708
A21: Leasing Commissions | B21: 0 | C21: =C9*Inputs!$B$35 -> 24300 | D21: =D9*Inputs!$B$35 -> 26419.5 | E21: =E9*Inputs!$B$35 -> 27212.085 | F21: =F9*Inputs!$B$35 -> 28028.448 | G21: =G9*Inputs!$B$35 -> 28869.301 | H21: =H9*Inputs!$B$35 -> 29735.38 | I21: =I9*Inputs!$B$35 -> 30627.441 | J21: =J9*Inputs!$B$35 -> 31546.265 | ... L21: =L9*Inputs!$B$35 -> 33467.432
A22: Repairs & Maintenance | B22: 0 | C22: =Inputs!$B$5*Inputs!$B$36 -> 25000 | D22: =Inputs!$B$5*Inputs!$B$36 -> 25000 | E22: =Inputs!$B$5*Inputs!$B$36 -> 25000 | F22: =Inputs!$B$5*Inputs!$B$36 -> 25000 | G22: =Inputs!$B$5*Inputs!$B$36 -> 25000 | H22: =Inputs!$B$5*Inputs!$B$36 -> 25000 | I22: =Inputs!$B$5*Inputs!$B$36 -> 25000 | J22: =Inputs!$B$5*Inputs!$B$36 -> 25000 | ... L22: =Inputs!$B$5*Inputs!$B$36 -> 25000
A23: Total Landlord Expenses | B23: 0 | C23: =SUM(C20:C22) -> 82348 | D23: =SUM(D20:D22) -> 87350.02 | E23: =SUM(E20:E22) -> 89220.521 | F23: =SUM(F20:F22) -> 91147.136 | G23: =SUM(G20:G22) -> 93131.55 | H23: =SUM(H20:H22) -> 95175.497 | I23: =SUM(I20:I22) -> 97280.762 | J23: =SUM(J20:J22) -> 99449.185 | ... L23: =SUM(L20:L22) -> 103983.14
A25: NET OPERATING INCOME (NOI) | B25: 0 | C25: =C11-C23 -> 743852 | D25: =D11-D23 -> 810912.98 | E25: =E11-E23 -> 835990.37 | F25: =F11-F23 -> 861820.08 | G25: =G11-G23 -> 888424.68 | H25: =H11-H23 -> 915827.42 | I25: =I11-I23 -> 944052.25 | J25: =J11-J23 -> 973123.81 | ... L25: =L11-L23 -> 1033909.6
A27: CAPITAL EXPENDITURES
A28: Initial Tenant Improvements | B28: =Inputs!$B$5*Inputs!$B$39 -> 250000 | C28: 0 | D28: 0 | E28: 0 | F28: 0 | G28: 0 | H28: 0 | I28: 0 | J28: 0 | K28: 0 | L28: 0
A29: Annual CapEx Reserve | B29: 0 | C29: =Inputs!$B$5*Inputs!$B$40 -> 37500 | D29: =Inputs!$B$5*Inputs!$B$40 -> 37500 | E29: =Inputs!$B$5*Inputs!$B$40 -> 37500 | F29: =Inputs!$B$5*Inputs!$B$40 -> 37500 | G29: =Inputs!$B$5*Inputs!$B$40 -> 37500 | H29: =Inputs!$B$5*Inputs!$B$40 -> 37500 | I29: =Inputs!$B$5*Inputs!$B$40 -> 37500 | J29: =Inputs!$B$5*Inputs!$B$40 -> 37500 | ... L29: =Inputs!$B$5*Inputs!$B$40 -> 37500
A30: Total CapEx | B30: =SUM(B28:B29) -> 250000 | C30: =SUM(C28:C29) -> 37500 | D30: =SUM(D28:D29) -> 37500 | E30: =SUM(E28:E29) -> 37500 | F30: =SUM(F28:F29) -> 37500 | G30: =SUM(G28:G29) -> 37500 | H30: =SUM(H28:H29) -> 37500 | I30: =SUM(I28:I29) -> 37500 | ... L30: =SUM(L28:L29) -> 37500
A32: Debt Service | B32: 0 | C32: =Inputs!$B$17 -> 662886.25 | D32: =Inputs!$B$17 -> 662886.25 | E32: =Inputs!$B$17 -> 662886.25 | F32: =Inputs!$B$17 -> 662886.25 | G32: =Inputs!$B$17 -> 662886.25 | H32: =Inputs!$B$17 -> 662886.25 | I32: =Inputs!$B$17 -> 662886.25 | J32: =Inputs!$B$17 -> 662886.25 | ... L32: =Inputs!$B$17 -> 662886.25
A34: CASH FLOW BEFORE TAX | B34: =-Inputs!$B$13-B30 -> -2825000 | C34: =C25-C30-C32 -> 43465.754 | D34: =D25-D30-D32 -> 110526.73 | E34: =E25-E30-E32 -> 135604.12 | F34: =F25-F30-F32 -> 161433.83 | G34: =G25-G30-G32 -> 188038.44 | H34: =H25-H30-H32 -> 215441.18 | I34: =I25-I30-I32 -> 243666 | J34: =J25-J30-J32 -> 272737.57 | ... L34: =L25-L30-L32 -> 333523.31
A36: KEY METRICS
A37: Cap Rate | B37: 0 | C37: =C25/Inputs!$B$6 -> 0.0743852 | D37: =D25/Inputs!$B$6 -> 0.081091298 | E37: =E25/Inputs!$B$6 -> 0.083599037 | F37: =F25/Inputs!$B$6 -> 0.086182008 | G37: =G25/Inputs!$B$6 -> 0.088842468 | H37: =H25/Inputs!$B$6 -> 0.091582742 | I37: =I25/Inputs!$B$6 -> 0.094405225 | J37: =J25/Inputs!$B$6 -> 0.097312381 | ... L37: =L25/Inputs!$B$6 -> 0.10339096
A38: DSCR | B38: 0 | C38: =IF(C32=0,0,C25/C32) -> 1.1221412 | D38: =IF(D32=0,0,D25/D32) -> 1.2233064 | E38: =IF(E32=0,0,E25/E32) -> 1.261137 | F38: =IF(F32=0,0,F25/F32) -> 1.3001025 | G38: =IF(G32=0,0,G25/G32) -> 1.340237 | H38: =IF(H32=0,0,H25/H32) -> 1.3815755 | I38: =IF(I32=0,0,I25/I32) -> 1.4241542 | J38: =IF(J32=0,0,J25/J32) -> 1.4680103 | ... L38: =IF(L32=0,0,L25/L32) -> 1.5597089
A39: Cash-on-Cash Return | B39: 0 | C39: =C34/Inputs!$B$13 -> 0.016879905 | D39: =D34/Inputs!$B$13 -> 0.042923004 | E39: =E34/Inputs!$B$13 -> 0.052661796 | F39: =F34/Inputs!$B$13 -> 0.062692751 | G39: =G34/Inputs!$B$13 -> 0.073024636 | H39: =H34/Inputs!$B$13 -> 0.083666477 | I39: =I34/Inputs!$B$13 -> 0.094627573 | J39: =J34/Inputs!$B$13 -> 0.1059175 | ... L39: =L34/Inputs!$B$13 -> 0.12952361
A41: Total CF incl. Exit | B41: =B34 -> -2825000 | C41: =C34 -> 43465.754 | D41: =D34 -> 110526.73 | E41: =E34 -> 135604.12 | F41: =F34 -> 161433.83 | G41: =G34 -> 188038.44 | H41: =H34 -> 215441.18 | I41: =I34 -> 243666 | ... K41: =K34 -> 302681.28 | L41: =L34+N10 -> 10351832

Sheet Returns
A1: Investment Returns Analysis
A3: EXIT VALUE (Year 10)
A5: Year 11 NOI (Projected) | B5: ='Pro Forma'!N5 -> 1064926.8
A6: Exit Cap Rate | B6: =Inputs!$B$43 -> 0.065
A7: Gross Sale Price | B7: ='Pro Forma'!N6 -> 16383490
A8: Less: Sale Costs | B8: ='Pro Forma'!N7 -> 327669.8
A9: Net Sale Proceeds | B9: ='Pro Forma'!N8 -> 16055820
A10: Less: Loan Balance | B10: ='Pro Forma'!N9 -> -6037510.9
A11: Net Cash from Sale | B11: ='Pro Forma'!N10 -> 10018309
A13: RETURN METRICS
A15: Total Equity Invested | B15: =Inputs!$B$13 -> 2575000
A16: Total Cash Flow (Yrs 1-10) | B16: =SUM('Pro Forma'!C34:L34) -> 2007118.2
A17: Net Cash from Sale | B17: =B11 -> 10018309
A18: Total Cash Returned | B18: =B16+B17 -> 12025427
A19: Total Profit | B19: =B18-B15 -> 9450427.4
A21: Equity Multiple | B21: =B18/B15 -> 4.6700689
A22: Average Annual Cash-on-Cash | B22: =AVERAGE('Pro Forma'!C39:L39) -> 0.077946339
A23: IRR (Internal Rate of Return) | B23: =IFERROR(IRR('Pro Forma'!B41:L41,0.15),0) -> 0.17091495
A24: NPV (Net Present Value) | B24: =NPV(Inputs!$B$47,'Pro Forma'!C33:L33)+'Pro Forma'!B33+B11/(1+Inputs!$B$47)^10 -> 3862491.9
A26: YEAR 1 METRICS
A28: Year 1 NOI | B28: ='Pro Forma'!C25 -> 743852
A29: Going-In Cap Rate | B29: ='Pro Forma'!C37 -> 0.0743852
A30: Year 1 DSCR | B30: ='Pro Forma'!C38 -> 1.1221412
A31: Year 1 Cash-on-Cash | B31: ='Pro Forma'!C39 -> 0.016879905
A33: INVESTMENT CRITERIA
A35: Metric | B35: Target | C35: Actual | D35: Pass/Fail
A36: IRR | B36: =Inputs!$B$48 -> 0.15 | C36: =B23 -> 0.17091495 | D36: =IF(C36>=B36,"PASS","FAIL") -> PASS
A37: Cash-on-Cash (Avg) | B37: =Inputs!$B$49 -> 0.08 | C37: =B22 -> 0.077946339 | D37: =IF(C37>=B37,"PASS","FAIL") -> FAIL
A38: DSCR (Year 1) | B38: 1.25 | C38: =IF(B30=0,0,B30) -> 1.1221412 | D38: =IF(C38>=B38,"PASS","FAIL") -> FAIL
A39: Equity Multiple | B39: 2 | C39: =B21 -> 4.6700689 | D39: =IF(C39>=B39,"PASS","FAIL") -> PASS

Sheet Sensitivity
A1: Sensitivity Analysis
A3: IRR Sensitivity: Exit Cap Rate vs Purchase Price
B4: Purchase Price → | C4: 8000000 | D4: 9000000 | E4: 10000000 | F4: 11000000 | G4: 12000000
A5: Exit Cap ↓ | B5: 0.055 | C5: 0.18 | D5: 0.16 | E5: 0.14 | F5: 0.12 | G5: 0.11
B6: 0.06 | C6: 0.17 | D6: 0.15 | E6: 0.13 | F6: 0.11 | G6: 0.1
B7: 0.065 | C7: 0.16 | D7: 0.14 | E7: =Returns!B23 -> 0.17091495 | F7: 0.1 | G7: 0.09
B8: 0.07 | C8: 0.15 | D8: 0.13 | E8: 0.11 | F8: 0.09 | G8: 0.08
B9: 0.075 | C9: 0.14 | D9: 0.12 | E9: 0.1 | F9: 0.08 | G9: 0.07
A12: Year 1 Cash-on-Cash: Rent/SF vs Occupancy
B13: Rent/SF → | C13: 16 | D13: 17 | E13: 18 | F13: 19 | G13: 20
A14: Occupancy ↓ | B14: 0.85 | C14: 0.04 | D14: 0.05 | E14: 0.06 | F14: 0.07 | G14: 0.08
B15: 0.9 | C15: 0.05 | D15: 0.06 | E15: 0.07 | F15: 0.08 | G15: 0.09
B16: 0.95 | C16: 0.06 | D16: 0.07 | E16: =Returns!B31 -> 0.016879905 | F16: 0.09 | G16: 0.1
B17: 1 | C17: 0.07 | D17: 0.08 | E17: 0.09 | F17: 0.1 | G17: 0.11
A20: NOTES:
A21: • Base case assumptions linked from Inputs sheet
A22: • Sensitivity tables show how returns vary with key assumptions
A23: • IRR: Shows impact of exit cap rate and purchase price
A24: • Cash-on-Cash: Shows impact of rent and occupancy
A25: • Modify blue inputs in Inputs sheet to update entire model
